Workbook

Sheet Getting Started
A1: Homeschool Curriculum Planner
A2: Getting Started · School & Student Information
B4: SCHOOL YEAR SETTINGS
B5: School Name: | C5: Westfield Academy
B6: School Year: | C6: 2025-2026
B7: School Days / Week: | C7: 5
B9: Semester 1 · September – December
B10: Sem 1 Start Date: | G10: ← MM/DD/YYYY
B11: Sem 1 End Date: | G11: ← MM/DD/YYYY
B12: Sem 1 Break Start: | G12: ← optional (e.g. Thanksgiving)
B13: Sem 1 Break End: | G13: ← optional
B14: Sem 1 Break Weeks: | C14: =IFERROR(IF(OR(C12="",C13=""),0,ROUNDDOWN((C13-C12)/7,0)),0) | G14: ← auto
B15: Sem 1 School Weeks: | C15: =IFERROR(ROUNDDOWN((C11-C10)/7,0)-C14,"") | G15: ← auto (total minus break)
B17: Semester 2 · January – May
B18: Sem 2 Start Date: | G18: ← MM/DD/YYYY
B19: Sem 2 End Date: | G19: ← MM/DD/YYYY
B20: Sem 2 Break Start: | G20: ← optional (e.g. Spring / Easter)
B21: Sem 2 Break End: | G21: ← optional
B22: Sem 2 Break Weeks: | C22: =IFERROR(IF(OR(C20="",C21=""),0,ROUNDDOWN((C21-C20)/7,0)),0) | G22: ← auto
B23: Sem 2 School Weeks: | C23: =IFERROR(ROUNDDOWN((C19-C18)/7,0)-C22,"") | G23: ← auto (total minus break)
B25: Total School Weeks: | C25: =IFERROR(C15+C23,"") | G25: ← Sem 1 + Sem 2 (breaks excluded)
A27: STUDENT ROSTER
A28: # | B28: Student Name | D28: Date of Birth | E28: Class of (Grad Year) | F28: Grade (Auto) | G28: Curriculum Notes
A29: 1 | F29: =IF(OR(B29="",E29=""),"",LET(yr,IF($C$19<>"",YEAR($C$19),IF($C$6<>"",VALUE(RIGHT($C$6,4)),YEAR(TODAY()))),g,12-(E29-yr),IF(g=11,"11th",IF(g=12,"12th",IF(g=1,"1st",IF(g=2,"2nd",IF(g=3,"3rd",g&"th")))))))
A30: 2 | F30: =IF(OR(B30="",E30=""),"",LET(yr,IF($C$19<>"",YEAR($C$19),IF($C$6<>"",VALUE(RIGHT($C$6,4)),YEAR(TODAY()))),g,12-(E30-yr),IF(g=11,"11th",IF(g=12,"12th",IF(g=1,"1st",IF(g=2,"2nd",IF(g=3,"3rd",g&"th")))))))
A31: 3 | F31: =IF(OR(B31="",E31=""),"",LET(yr,IF($C$19<>"",YEAR($C$19),IF($C$6<>"",VALUE(RIGHT($C$6,4)),YEAR(TODAY()))),g,12-(E31-yr),IF(g=11,"11th",IF(g=12,"12th",IF(g=1,"1st",IF(g=2,"2nd",IF(g=3,"3rd",g&"th")))))))
A32: 4 | F32: =IF(OR(B32="",E32=""),"",LET(yr,IF($C$19<>"",YEAR($C$19),IF($C$6<>"",VALUE(RIGHT($C$6,4)),YEAR(TODAY()))),g,12-(E32-yr),IF(g=11,"11th",IF(g=12,"12th",IF(g=1,"1st",IF(g=2,"2nd",IF(g=3,"3rd",g&"th")))))))
A33: 5 | F33: =IF(OR(B33="",E33=""),"",LET(yr,IF($C$19<>"",YEAR($C$19),IF($C$6<>"",VALUE(RIGHT($C$6,4)),YEAR(TODAY()))),g,12-(E33-yr),IF(g=11,"11th",IF(g=12,"12th",IF(g=1,"1st",IF(g=2,"2nd",IF(g=3,"3rd",g&"th")))))))
A34: 6 | F34: =IF(OR(B34="",E34=""),"",LET(yr,IF($C$19<>"",YEAR($C$19),IF($C$6<>"",VALUE(RIGHT($C$6,4)),YEAR(TODAY()))),g,12-(E34-yr),IF(g=11,"11th",IF(g=12,"12th",IF(g=1,"1st",IF(g=2,"2nd",IF(g=3,"3rd",g&"th")))))))
A35: 7 | F35: =IF(OR(B35="",E35=""),"",LET(yr,IF($C$19<>"",YEAR($C$19),IF($C$6<>"",VALUE(RIGHT($C$6,4)),YEAR(TODAY()))),g,12-(E35-yr),IF(g=11,"11th",IF(g=12,"12th",IF(g=1,"1st",IF(g=2,"2nd",IF(g=3,"3rd",g&"th")))))))
A36: 8 | F36: =IF(OR(B36="",E36=""),"",LET(yr,IF($C$19<>"",YEAR($C$19),IF($C$6<>"",VALUE(RIGHT($C$6,4)),YEAR(TODAY()))),g,12-(E36-yr),IF(g=11,"11th",IF(g=12,"12th",IF(g=1,"1st",IF(g=2,"2nd",IF(g=3,"3rd",g&"th")))))))
A37: 9 | F37: =IF(OR(B37="",E37=""),"",LET(yr,IF($C$19<>"",YEAR($C$19),IF($C$6<>"",VALUE(RIGHT($C$6,4)),YEAR(TODAY()))),g,12-(E37-yr),IF(g=11,"11th",IF(g=12,"12th",IF(g=1,"1st",IF(g=2,"2nd",IF(g=3,"3rd",g&"th")))))))
A38: 10 | F38: =IF(OR(B38="",E38=""),"",LET(yr,IF($C$19<>"",YEAR($C$19),IF($C$6<>"",VALUE(RIGHT($C$6,4)),YEAR(TODAY()))),g,12-(E38-yr),IF(g=11,"11th",IF(g=12,"12th",IF(g=1,"1st",IF(g=2,"2nd",IF(g=3,"3rd",g&"th")))))))
A40: QUICK START GUIDE
A41: 1. Set semester dates above (Sem 1 and Sem 2) — week counts auto-calculate.
A42: 2. Enter each student's name, DOB, and graduation year — grade fills automatically.
A43: 3. Go to the Course Content tab to assign curricula to each student.
A44: 4. Each student's individual schedule tab will auto-populate from Course Content.

Sheet Course Content
A1: Course Content · Curriculum Planning Hub
A2: Each subject has two curriculum slots. Group Studies apply to all students. Use the ＋ / − buttons on the left to expand or collapse each student.
A4: Tip: click the − button beside a student's name to collapse their rows. Expand only the student you're currently planning for.
A5: Subject | B5: ── Curriculum Slot 1 ── | G5: ── Curriculum Slot 2 ──
B6: Title / Book | C6: Unit Type | D6: Sem 1 Units | E6: Sem 2 Units | G6: Title / Book | H6: Unit Type | I6: Sem 1 Units | J6: Sem 2 Units
A7: GROUP STUDIES · Applies to All Students
A8: Bible | C8: pages | H8: pages
A9: Math | C9: pages | H9: pages
A10: English / Language Arts | C10: pages | H10: pages
A11: Reading | C11: pages | H11: pages
A12: Writing / Composition | C12: pages | H12: pages
A13: Science | C13: pages | H13: pages
A14: Social Studies / History | C14: pages | H14: pages
A15: Health | C15: pages | H15: pages
A16: Physical Education | C16: pages | H16: pages
A17: Art / Music | C17: pages | H17: pages
A18: Elective / Other 1 | C18: pages | H18: pages
A19: Elective / Other 2 | C19: pages | H19: pages
... A21: Elective / Other 4 | C21: pages | H21: pages
A23: =IF('Getting Started'!B29<>""," "&UPPER('Getting Started'!B29)&" · "&'Getting Started'!F29," STUDENT 1")
A24: Bible | C24: pages | H24: pages
A25: Math | C25: pages | H25: pages
A26: English / Language Arts | C26: pages | H26: pages
A27: Reading | C27: pages | H27: pages
A28: Writing / Composition | C28: pages | H28: pages
A29: Science | C29: pages | H29: pages
A30: Social Studies / History | C30: pages | H30: pages
A31: Health | C31: pages | H31: pages
A32: Physical Education | C32: pages | H32: pages
A33: Art / Music | C33: pages | H33: pages
A34: Elective / Other 1 | C34: pages | H34: pages
A35: Elective / Other 2 | C35: pages | H35: pages
... A37: Elective / Other 4 | C37: pages | H37: pages
A39: =IF('Getting Started'!B30<>""," "&UPPER('Getting Started'!B30)&" · "&'Getting Started'!F30," STUDENT 2")
A40: Bible | C40: pages | H40: pages
A41: Math | C41: pages | H41: pages
A42: English / Language Arts | C42: pages | H42: pages
A43: Reading | C43: pages | H43: pages
A44: Writing / Composition | C44: pages | H44: pages
A45: Science | C45: pages | H45: pages
...

Sheet Student 1
A1: =IF('Getting Started'!B29="","Student 1",'Getting Started'!B29)
A2: =IFERROR("Grade: "&'Getting Started'!F29&" · School Year: "&'Getting Started'!C6,"")
A4: =IFERROR("SEMESTER 1 "&TEXT('Getting Started'!C10,"MMM D")&" – "&TEXT('Getting Started'!C11,"MMM D, YYYY")&" ("&'Getting Started'!C15&" wks)","SEMESTER 1") | G4: =IFERROR("SEMESTER 2 "&TEXT('Getting Started'!C18,"MMM D")&" – "&TEXT('Getting Started'!C19,"MMM D, YYYY")&" ("&'Getting Started'!C23&" wks)","SEMESTER 2")
A5: Subject / Curriculum | B5: Sem 1 Units | C5: / Week | D5: / Day | E5: Est. End | G5: Sem 2 Units | H5: / Week | I5: / Day | J5: Est. End
A7: BIBLE | E7: =IFERROR(IF('Course Content'!B24="","← enter on Course Content tab",'Course Content'!B24),"")
B8: ='Course Content'!D24 | C8: =IFERROR(IF(B8="","",ROUND(B8/'Getting Started'!C15,1)),"") | D8: =IFERROR(IF(C8="","",ROUND(C8/'Getting Started'!C7,1)),"") | E8: =IFERROR(IF(B8="","",TEXT('Getting Started'!C10+(B8/D8),"MMM D, YYYY")),"") | G8: ='Course Content'!E24 | H8: =IFERROR(IF(G8="","",ROUND(G8/'Getting Started'!C23,1)),"") | I8: =IFERROR(IF(H8="","",ROUND(H8/'Getting Started'!C7,1)),"") | J8: =IFERROR(IF(G8="","",TEXT('Getting Started'!C18+(G8/I8),"MMM D, YYYY")),"")
A9: Component Breakdown (optional — use for multi-volume curricula)
A10: # | B10: Book / Component Title | F10: Units | G10: Cumul. | H10: Start Week | I10: End Week | J10: Est. Dates
A11: 1 | G11: =IFERROR(SUM(F11:F11),"") | H11: =IF(F11="","",1) | I11: =IFERROR(IF(F11="","",CEILING(G11/((IFERROR(B8,0)+IFERROR(G8,0))/(IFERROR('Getting Started'!C15,0)+IFERROR('Getting Started'!C23,0))),1)),"") | J11: =IFERROR(IF(F11="","",TEXT('Getting Started'!C10+(H11-1)*7,"MMM D")&" – "&TEXT('Getting Started'!C10+I11*7,"MMM D")),"")
A12: 2 | G12: =IFERROR(SUM(F11:F12),"") | H12: =IFERROR(IF(F12="","",FLOOR(G11/((IFERROR(B8,0)+IFERROR(G8,0))/(IFERROR('Getting Started'!C15,0)+IFERROR('Getting Started'!C23,0))),1)+1),"") | I12: =IFERROR(IF(F12="","",CEILING(G12/((IFERROR(B8,0)+IFERROR(G8,0))/(IFERROR('Getting Started'!C15,0)+IFERROR('Getting Started'!C23,0))),1)),"") | J12: =IFERROR(IF(F12="","",TEXT('Getting Started'!C10+(H12-1)*7,"MMM D")&" – "&TEXT('Getting Started'!C10+I12*7,"MMM D")),"")
A13: 3 | G13: =IFERROR(SUM(F11:F13),"") | H13: =IFERROR(IF(F13="","",FLOOR(G12/((IFERROR(B8,0)+IFERROR(G8,0))/(IFERROR('Getting Started'!C15,0)+IFERROR('Getting Started'!C23,0))),1)+1),"") | I13: =IFERROR(IF(F13="","",CEILING(G13/((IFERROR(B8,0)+IFERROR(G8,0))/(IFERROR('Getting Started'!C15,0)+IFERROR('Getting Started'!C23,0))),1)),"") | J13: =IFERROR(IF(F13="","",TEXT('Getting Started'!C10+(H13-1)*7,"MMM D")&" – "&TEXT('Getting Started'!C10+I13*7,"MMM D")),"")
A14: 4 | G14: =IFERROR(SUM(F11:F14),"") | H14: =IFERROR(IF(F14="","",FLOOR(G13/((IFERROR(B8,0)+IFERROR(G8,0))/(IFERROR('Getting Started'!C15,0)+IFERROR('Getting Started'!C23,0))),1)+1),"") | I14: =IFERROR(IF(F14="","",CEILING(G14/((IFERROR(B8,0)+IFERROR(G8,0))/(IFERROR('Getting Started'!C15,0)+IFERROR('Getting Started'!C23,0))),1)),"") | J14: =IFERROR(IF(F14="","",TEXT('Getting Started'!C10+(H14-1)*7,"MMM D")&" – "&TEXT('Getting Started'!C10+I14*7,"MMM D")),"")
A15: 5 | G15: =IFERROR(SUM(F11:F15),"") | H15: =IFERROR(IF(F15="","",FLOOR(G14/((IFERROR(B8,0)+IFERROR(G8,0))/(IFERROR('Getting Started'!C15,0)+IFERROR('Getting Started'!C23,0))),1)+1),"") | I15: =IFERROR(IF(F15="","",CEILING(G15/((IFERROR(B8,0)+IFERROR(G8,0))/(IFERROR('Getting Started'!C15,0)+IFERROR('Getting Started'!C23,0))),1)),"") | J15: =IFERROR(IF(F15="","",TEXT('Getting Started'!C10+(H15-1)*7,"MMM D")&" – "&TEXT('Getting Started'!C10+I15*7,"MMM D")),"")
A16: 6 | G16: =IFERROR(SUM(F11:F16),"") | H16: =IFERROR(IF(F16="","",FLOOR(G15/((IFERROR(B8,0)+IFERROR(G8,0))/(IFERROR('Getting Started'!C15,0)+IFERROR('Getting Started'!C23,0))),1)+1),"") | I16: =IFERROR(IF(F16="","",CEILING(G16/((IFERROR(B8,0)+IFERROR(G8,0))/(IFERROR('Getting Started'!C15,0)+IFERROR('Getting Started'!C23,0))),1)),"") | J16: =IFERROR(IF(F16="","",TEXT('Getting Started'!C10+(H16-1)*7,"MMM D")&" – "&TEXT('Getting Started'!C10+I16*7,"MMM D")),"")
A19: MATH | E19: =IFERROR(IF('Course Content'!B25="","← enter on Course Content tab",'Course Content'!B25),"")
B20: ='Course Content'!D25 | C20: =IFERROR(IF(B20="","",ROUND(B20/'Getting Started'!C15,1)),"") | D20: =IFERROR(IF(C20="","",ROUND(C20/'Getting Started'!C7,1)),"") | E20: =IFERROR(IF(B20="","",TEXT('Getting Started'!C10+(B20/D20),"MMM D, YYYY")),"") | G20: ='Course Content'!E25 | H20: =IFERROR(IF(G20="","",ROUND(G20/'Getting Started'!C23,1)),"") | I20: =IFERROR(IF(H20="","",ROUND(H20/'Getting Started'!C7,1)),"") | J20: =IFERROR(IF(G20="","",TEXT('Getting Started'!C18+(G20/I20),"MMM D, YYYY")),"")
A21: Component Breakdown (optional — use for multi-volume curricula)
A22: # | B22: Book / Component Title | F22: Units | G22: Cumul. | H22: Start Week | I22: End Week | J22: Est. Dates
A23: 1 | G23: =IFERROR(SUM(F23:F23),"") | H23: =IF(F23="","",1) | I23: =IFERROR(IF(F23="","",CEILING(G23/((IFERROR(B20,0)+IFERROR(G20,0))/(IFERROR('Getting Started'!C15,0)+IFERROR('Getting Started'!C23,0))),1)),"") | J23: =IFERROR(IF(F23="","",TEXT('Getting Started'!C10+(H23-1)*7,"MMM D")&" – "&TEXT('Getting Started'!C10+I23*7,"MMM D")),"")
A24: 2 | G24: =IFERROR(SUM(F23:F24),"") | H24: =IFERROR(IF(F24="","",FLOOR(G23/((IFERROR(B20,0)+IFERROR(G20,0))/(IFERROR('Getting Started'!C15,0)+IFERROR('Getting Started'!C23,0))),1)+1),"") | I24: =IFERROR(IF(F24="","",CEILING(G24/((IFERROR(B20,0)+IFERROR(G20,0))/(IFERROR('Getting Started'!C15,0)+IFERROR('Getting Started'!C23,0))),1)),"") | J24: =IFERROR(IF(F24="","",TEXT('Getting Started'!C10+(H24-1)*7,"MMM D")&" – "&TEXT('Getting Started'!C10+I24*7,"MMM D")),"")
A25: 3 | G25: =IFERROR(SUM(F23:F25),"") | H25: =IFERROR(IF(F25="","",FLOOR(G24/((IFERROR(B20,0)+IFERROR(G20,0))/(IFERROR('Getting Started'!C15,0)+IFERROR('Getting Started'!C23,0))),1)+1),"") | I25: =IFERROR(IF(F25="","",CEILING(G25/((IFERROR(B20,0)+IFERROR(G20,0))/(IFERROR('Getting Started'!C15,0)+IFERROR('Getting Started'!C23,0))),1)),"") | J25: =IFERROR(IF(F25="","",TEXT('Getting Started'!C10+(H25-1)*7,"MMM D")&" – "&TEXT('Getting Started'!C10+I25*7,"MMM D")),"")
A26: 4 | G26: =IFERROR(SUM(F23:F26),"") | H26: =IFERROR(IF(F26="","",FLOOR(G25/((IFERROR(B20,0)+IFERROR(G20,0))/(IFERROR('Getting Started'!C15,0)+IFERROR('Getting Started'!C23,0))),1)+1),"") | I26: =IFERROR(IF(F26="","",CEILING(G26/((IFERROR(B20,0)+IFERROR(G20,0))/(IFERROR('Getting Started'!C15,0)+IFERROR('Getting Started'!C23,0))),1)),"") | J26: =IFERROR(IF(F26="","",TEXT('Getting Started'!C10+(H26-1)*7,"MMM D")&" – "&TEXT('Getting Started'!C10+I26*7,"MMM D")),"")
A27: 5 | G27: =IFERROR(SUM(F23:F27),"") | H27: =IFERROR(IF(F27="","",FLOOR(G26/((IFERROR(B20,0)+IFERROR(G20,0))/(IFERROR('Getting Started'!C15,0)+IFERROR('Getting Started'!C23,0))),1)+1),"") | I27: =IFERROR(IF(F27="","",CEILING(G27/((IFERROR(B20,0)+IFERROR(G20,0))/(IFERROR('Getting Started'!C15,0)+IFERROR('Getting Started'!C23,0))),1)),"") | J27: =IFERROR(IF(F27="","",TEXT('Getting Started'!C10+(H27-1)*7,"MMM D")&" – "&TEXT('Getting Started'!C10+I27*7,"MMM D")),"")
A28: 6 | G28: =IFERROR(SUM(F23:F28),"") | H28: =IFERROR(IF(F28="","",FLOOR(G27/((IFERROR(B20,0)+IFERROR(G20,0))/(IFERROR('Getting Started'!C15,0)+IFERROR('Getting Started'!C23,0))),1)+1),"") | I28: =IFERROR(IF(F28="","",CEILING(G28/((IFERROR(B20,0)+IFERROR(G20,0))/(IFERROR('Getting Started'!C15,0)+IFERROR('Getting Started'!C23,0))),1)),"") | J28: =IFERROR(IF(F28="","",TEXT('Getting Started'!C10+(H28-1)*7,"MMM D")&" – "&TEXT('Getting Started'!C10+I28*7,"MMM D")),"")
A31: ENGLISH / LANGUAGE ARTS | E31: =IFERROR(IF('Course Content'!B26="","← enter on Course Content tab",'Course Content'!B26),"")
B32: ='Course Content'!D26 | C32: =IFERROR(IF(B32="","",ROUND(B32/'Getting Started'!C15,1)),"") | D32: =IFERROR(IF(C32="","",ROUND(C32/'Getting Started'!C7,1)),"") | E32: =IFERROR(IF(B32="","",TEXT('Getting Started'!C10+(B32/D32),"MMM D, YYYY")),"") | G32: ='Course Content'!E26 | H32: =IFERROR(IF(G32="","",ROUND(G32/'Getting Started'!C23,1)),"") | I32: =IFERROR(IF(H32="","",ROUND(H32/'Getting Started'!C7,1)),"") | J32: =IFERROR(IF(G32="","",TEXT('Getting Started'!C18+(G32/I32),"MMM D, YYYY")),"")
A33: Component Breakdown (optional — use for multi-volume curricula)
A34: # | B34: Book / Component Title | F34: Units | G34: Cumul. | H34: Start Week | I34: End Week | J34: Est. Dates
A35: 1 | G35: =IFERROR(SUM(F35:F35),"") | H35: =IF(F35="","",1) | I35: =IFERROR(IF(F35="","",CEILING(G35/((IFERROR(B32,0)+IFERROR(G32,0))/(IFERROR('Getting Started'!C15,0)+IFERROR('Getting Started'!C23,0))),1)),"") | J35: =IFERROR(IF(F35="","",TEXT('Getting Started'!C10+(H35-1)*7,"MMM D")&" – "&TEXT('Getting Started'!C10+I35*7,"MMM D")),"")
A36: 2 | G36: =IFERROR(SUM(F35:F36),"") | H36: =IFERROR(IF(F36="","",FLOOR(G35/((IFERROR(B32,0)+IFERROR(G32,0))/(IFERROR('Getting Started'!C15,0)+IFERROR('Getting Started'!C23,0))),1)+1),"") | I36: =IFERROR(IF(F36="","",CEILING(G36/((IFERROR(B32,0)+IFERROR(G32,0))/(IFERROR('Getting Started'!C15,0)+IFERROR('Getting Started'!C23,0))),1)),"") | J36: =IFERROR(IF(F36="","",TEXT('Getting Started'!C10+(H36-1)*7,"MMM D")&" – "&TEXT('Getting Started'!C10+I36*7,"MMM D")),"")
A37: 3 | G37: =IFERROR(SUM(F35:F37),"") | H37: =IFERROR(IF(F37="","",FLOOR(G36/((IFERROR(B32,0)+IFERROR(G32,0))/(IFERROR('Getting Started'!C15,0)+IFERROR('Getting Started'!C23,0))),1)+1),"") | I37: =IFERROR(IF(F37="","",CEILING(G37/((IFERROR(B32,0)+IFERROR(G32,0))/(IFERROR('Getting Started'!C15,0)+IFERROR('Getting Started'!C23,0))),1)),"") | J37: =IFERROR(IF(F37="","",TEXT('Getting Started'!C10+(H37-1)*7,"MMM D")&" – "&TEXT('Getting Started'!C10+I37*7,"MMM D")),"")
A38: 4 | G38: =IFERROR(SUM(F35:F38),"") | H38: =IFERROR(IF(F38="","",FLOOR(G37/((IFERROR(B32,0)+IFERROR(G32,0))/(IFERROR('Getting Started'!C15,0)+IFERROR('Getting Started'!C23,0))),1)+1),"") | I38: =IFERROR(IF(F38="","",CEILING(G38/((IFERROR(B32,0)+IFERROR(G32,0))/(IFERROR('Getting Started'!C15,0)+IFERROR('Getting Started'!C23,0))),1)),"") | J38: =IFERROR(IF(F38="","",TEXT('Getting Started'!C10+(H38-1)*7,"MMM D")&" – "&TEXT('Getting Started'!C10+I38*7,"MMM D")),"")
A39: 5 | G39: =IFERROR(SUM(F35:F39),"") | H39: =IFERROR(IF(F39="","",FLOOR(G38/((IFERROR(B32,0)+IFERROR(G32,0))/(IFERROR('Getting Started'!C15,0)+IFERROR('Getting Started'!C23,0))),1)+1),"") | I39: =IFERROR(IF(F39="","",CEILING(G39/((IFERROR(B32,0)+IFERROR(G32,0))/(IFERROR('Getting Started'!C15,0)+IFERROR('Getting Started'!C23,0))),1)),"") | J39: =IFERROR(IF(F39="","",TEXT('Getting Started'!C10+(H39-1)*7,"MMM D")&" – "&TEXT('Getting Started'!C10+I39*7,"MMM D")),"")
A40: 6 | G40: =IFERROR(SUM(F35:F40),"") | H40: =IFERROR(IF(F40="","",FLOOR(G39/((IFERROR(B32,0)+IFERROR(G32,0))/(IFERROR('Getting Started'!C15,0)+IFERROR('Getting Started'!C23,0))),1)+1),"") | I40: =IFERROR(IF(F40="","",CEILING(G40/((IFERROR(B32,0)+IFERROR(G32,0))/(IFERROR('Getting Started'!C15,0)+IFERROR('Getting Started'!C23,0))),1)),"") | J40: =IFERROR(IF(F40="","",TEXT('Getting Started'!C10+(H40-1)*7,"MMM D")&" – "&TEXT('Getting Started'!C10+I40*7,"MMM D")),"")
A43: READING | E43: =IFERROR(IF('Course Content'!B27="","← enter on Course Content tab",'Course Content'!B27),"")
B44: ='Course Content'!D27 | C44: =IFERROR(IF(B44="","",ROUND(B44/'Getting Started'!C15,1)),"") | D44: =IFERROR(IF(C44="","",ROUND(C44/'Getting Started'!C7,1)),"") | E44: =IFERROR(IF(B44="","",TEXT('Getting Started'!C10+(B44/D44),"MMM D, YYYY")),"") | G44: ='Course Content'!E27 | H44: =IFERROR(IF(G44="","",ROUND(G44/'Getting Started'!C23,1)),"") | I44: =IFERROR(IF(H44="","",ROUND(H44/'Getting Started'!C7,1)),"") | J44: =IFERROR(IF(G44="","",TEXT('Getting Started'!C18+(G44/I44),"MMM D, YYYY")),"")
A45: Component Breakdown (optional — use for multi-volume curricula)
A46: # | B46: Book / Component Title | F46: Units | G46: Cumul. | H46: Start Week | I46: End Week | J46: Est. Dates
A47: 1 | G47: =IFERROR(SUM(F47:F47),"") | H47: =IF(F47="","",1) | I47: =IFERROR(IF(F47="","",CEILING(G47/((IFERROR(B44,0)+IFERROR(G44,0))/(IFERROR('Getting Started'!C15,0)+IFERROR('Getting Started'!C23,0))),1)),"") | J47: =IFERROR(IF(F47="","",TEXT('Getting Started'!C10+(H47-1)*7,"MMM D")&" – "&TEXT('Getting Started'!C10+I47*7,"MMM D")),"")
A48: 2 | G48: =IFERROR(SUM(F47:F48),"") | H48: =IFERROR(IF(F48="","",FLOOR(G47/((IFERROR(B44,0)+IFERROR(G44,0))/(IFERROR('Getting Started'!C15,0)+IFERROR('Getting Started'!C23,0))),1)+1),"") | I48: =IFERROR(IF(F48="","",CEILING(G48/((IFERROR(B44,0)+IFERROR(G44,0))/(IFERROR('Getting Started'!C15,0)+IFERROR('Getting Started'!C23,0))),1)),"") | J48: =IFERROR(IF(F48="","",TEXT('Getting Started'!C10+(H48-1)*7,"MMM D")&" – "&TEXT('Getting Started'!C10+I48*7,"MMM D")),"")
...
